{
  "modified": "2025-09-26T09:13:51Z",
  "published": "2025-09-26T09:13:51Z",
  "schema_version": "1.5.0",
  "id": "",
  "aliases": [
    "MAL-2025-2950",
    "SNYK-PYTHON-CREDENTIALPYTHONSDK-12201349"
  ],
  "affected": [
    {
      "package": {
        "ecosystem": "PyPI",
        "name": "credential-python-sdk"
      }
    }
  ],
  "references": [
    {
      "type": "WEB",
      "url": "https://x.com/ReversingLabs/status/1900198602242204003"
    },
    {
      "type": "ADVISORY",
      "url": "https://security.snyk.io/vuln/SNYK-PYTHON-CREDENTIALPYTHONSDK-12201349"
    },
    {
      "type": "ADVISORY",
      "url": "https://github.com/ossf/malicious-packages/blob/main/osv/malicious/pypi/credential-python-sdk/MAL-2025-2950.json"
    }
  ],
  "database_specific": {
    "malicious-packages-origins": [
      {
        "source": "reversing-labs",
        "sha256": "ccb75be9c570fba4a5794bea20205e89e2d4e5f8d24d654e0cb08c6729ee1435",
        "import_time": "2025-09-26T11:06:10.062827406Z",
        "id": "RLUA-2025-04755",
        "modified_time": "2025-09-26T09:13:51Z"
      }
    ]
  }
}
